<?xml version="1.0" ?>
<sdf version="1.5">
  <model name="jeep">
    <static>false</static>
    <link name="base_link">
      <inertial>
        <mass>720.0</mass>
        <inertia>
          <ixx>140</ixx>
          <ixy>0.0</ixy>
          <iyy>550</iyy>
          <ixz>0.0</ixz>
          <iyz>0.0</iyz>
          <izz>550</izz>
        </inertia>
        <pose>0.1 0 0.4 0 0 0</pose>
      </inertial>
      <pose frame=''>-0 0 0.07 0 -0 0</pose>
      <visual name="visual">
        <pose>0 0 0 0 0 -1.5708</pose>
        <geometry>
          <mesh>
            <scale>1 1 1</scale>
            <uri>model://jeep/meshes/body_car.stl</uri>
          </mesh>
        </geometry>
        <material>
          <script>
            <uri>file://media/materials/scripts/gazebo.material</uri>            
            <name>Gazebo/DarkGrey</name>
          </script>
        </material>
      </visual>

      <visual name="seat_r">
        <pose>0 0 0 0 0 -1.5708</pose>
        <geometry>
          <mesh>
            <scale>1 1 1</scale>
            <uri>model://jeep/meshes/seat_r.stl</uri>
          </mesh>
        </geometry>
        <material>
          <script>
            <uri>file://media/materials/scripts/gazebo.material</uri>            
            <name>Gazebo/DarkGrey</name>
          </script>
        </material>
      </visual>

      <visual name="seat_l">
        <pose>0 0 0 0 0 -1.5708</pose>
        <geometry>
          <mesh>
            <scale>1 1 1</scale>
            <uri>model://jeep/meshes/seat_l.stl</uri>
          </mesh>
        </geometry>
        <material>
          <script>
            <uri>file://media/materials/scripts/gazebo.material</uri>            
            <name>Gazebo/DarkGrey</name>
          </script>
        </material>
      </visual>


      <visual name="spare_wheel">
        <pose>0 0 0 0 0 -1.5708</pose>
        <geometry>
          <mesh>
            <scale>1 1 1</scale>
            <uri>model://jeep/meshes/spare_wheel.stl</uri>
          </mesh>
        </geometry>
        <material>
          <script>
            <uri>file://media/materials/scripts/gazebo.material</uri>            
            <name>Gazebo/DarkGrey</name>
          </script>
        </material>
      </visual>

      <visual name="steering_wheel">
        <pose>0 0 0 0 0 -1.5708</pose>
        <geometry>
          <mesh>
            <scale>1 1 1</scale>
            <uri>model://jeep/meshes/steering_wheel.stl</uri>
          </mesh>
        </geometry>
        <material>
          <script>
            <uri>file://media/materials/scripts/gazebo.material</uri>            
            <name>Gazebo/DarkGrey</name>
          </script>
        </material>
      </visual>

      <visual name="front_window">
        <pose>0 0 0 0 0 -1.5708</pose>
        <geometry>
          <mesh>
            <scale>1 1 1</scale>
            <uri>model://jeep/meshes/front_window.stl</uri>
          </mesh>
        </geometry>
        <material>
          <script>
            <uri>file://media/materials/scripts/gazebo.material</uri>            
            <name>Gazebo/DarkGrey</name>
          </script>
        </material>
      </visual>

      <collision name="base_link_bottom">
        <pose>-0.280000 0.0 0.335 0 0 0</pose>
        <geometry>
          <box>
            <size>1.34 1.65746 0.06</size>
          </box>
        </geometry>
      </collision>
      <collision name="cargo_bottom">
        <pose>-1.680000 0.0 0.701000 0.0 0.0 0.0</pose>
        <geometry>
          <box>
            <size>1.04609 1.6998 0.01</size>
          </box>
        </geometry>
      </collision>
      <collision name="cargo_back">
        <pose>-2.215000 0.0 0.850000 0.0 0.0 0.0</pose>
        <geometry>
          <box>
            <size>0.05 1.69982 0.27</size>
          </box>
        </geometry>
      </collision>
      <collision name="cargo_left">
        <pose>-1.705000 0.82491 0.850000 0.0 0.0 0.0</pose>
        <geometry>
          <box>
            <size>1.04609 0.05 0.27</size>
          </box>
        </geometry>
      </collision>
      <collision name="cargo_right">
        <pose>-1.705000 -0.82491 0.850000 0.0 0.0 0.0</pose>
        <geometry>
          <box>
            <size>1.04609 0.05 0.27</size>
          </box>
        </geometry>
      </collision>
      <collision name="seat">
        <pose>-0.540000 0.0 0.62 0 0 0</pose>
        <geometry>
          <box>
            <size>0.52167 1.37206 0.53369</size>
          </box>
        </geometry>
        <surface>
          <contact>
            <ode>
              <min_depth>0.01</min_depth>
            </ode>
          </contact>
        </surface>
      </collision>
      <collision name="mud_seat">
        <pose>-0.54000 0.0 0.86 0 0 0</pose>
        <geometry>
          <box>
            <size>0.52167 1.30 0.1</size>
          </box>
        </geometry>
        <surface>
          <contact>
            <collide_without_contact>true</collide_without_contact>
          </contact>
        </surface>
      </collision>
      <sensor name="seat_contact" type="contact">
        <always_on>true</always_on>
        <update_rate>1000</update_rate>
        <contact>
          <collision>mud_seat</collision>
        </contact>
      </sensor>
      <collision name="seat_back">
        <pose>-0.830000 0.0 1.125 0.0 -0.2 0.0</pose>
        <geometry>
          <box>
            <size>0.06 1.37206 0.6</size>
          </box>
        </geometry>
      </collision>
      <collision name="engine">
        <pose>0.89 0.0 0.75 0.0 0.0 0.0</pose>
        <geometry>
          <box>
            <size>1.4 1.8 0.8</size>
          </box>
        </geometry>
      </collision>
      <collision name="rollcage_top_front">
        <pose>0.065000 0.0 1.7 0 1.230000 0</pose>
        <geometry>
          <box>
            <size>0.01299 1.54 0.10226</size>
          </box>
        </geometry>
      </collision>
      <collision name="rollcage_front_left">
        <pose>0.112000 -0.885 1.440000 0 -0.270000 0</pose>
        <geometry>
          <cylinder>
            <radius>0.03</radius>
            <length>0.55</length>
          </cylinder>
        </geometry>
      </collision>
      <collision name="rollcage_front_right">
        <pose>0.112000 0.885 1.440000 0 -0.54 0</pose>
        <geometry>
          <cylinder>
            <radius>0.03</radius>
            <length>0.55</length>
          </cylinder>
        </geometry>
      </collision>
    </link>
    <link name='jeep/imu_link'>
      <pose>0 0 0 0 0 0</pose>
      <inertial>
        <pose>0 0 0 0 0 0</pose>
        <mass>0.015</mass>
        <inertia>
          <ixx>1e-05</ixx>
          <ixy>0</ixy>
          <ixz>0</ixz>
          <iyy>1e-05</iyy>
          <iyz>0</iyz>
          <izz>1e-05</izz>
        </inertia>
      </inertial>
    </link>
    <joint name='jeep/imu_joint' type='revolute'>
      <child>jeep/imu_link</child>
      <parent>base_link</parent>
      <axis>
        <xyz>1 0 0</xyz>
        <limit>
          <lower>0</lower>
          <upper>0</upper>
          <effort>0</effort>
          <velocity>0</velocity>
        </limit>
        <dynamics>
          <spring_reference>0</spring_reference>
          <spring_stiffness>0</spring_stiffness>
        </dynamics>
        <use_parent_model_frame>1</use_parent_model_frame>
      </axis>
    </joint>
    <link name="front_left_wheel">
      <pose>1.082230 0.71562 0.416970 -1.52 0.0 0.0</pose>
      <inertial>
        <mass>12</mass>
        <!-- estimated from http://www.rzrforums.net/wheels-tires/1729-tire-wheel-weights-most-sizes.html -->
        <inertia>
          <ixx>0.5</ixx>
          <ixy>0.0</ixy>
          <iyy>0.5</iyy>
          <ixz>0.0</ixz>
          <iyz>0.0</iyz>
          <izz>1.0</izz>
        </inertia>
      </inertial>
      <collision name="collision">
        <pose>0 0 0.21 0 0.0 0.0</pose>
        <geometry>
          <cylinder>
            <radius>0.417500</radius>
            <length>0.239400</length>
          </cylinder>
        </geometry>
        <max_contacts>1</max_contacts>
        <surface>
          <friction>
            <ode>
              <mu>1.0</mu>
              <mu2>1.0</mu2>
              <fdir1>0 0 1</fdir1>
              <slip1>0.0</slip1>
              <slip2>0.0</slip2>
            </ode>
          </friction>
          <contact>
            <ode>
              <min_depth>0.005</min_depth>
              <kp>1e8</kp>
            </ode>
          </contact>
        </surface>
      </collision>
      <visual name="visual">
        <pose>-0.3063 1.476200 -0.663800 0 1.570796 0</pose>
        <geometry>
          <mesh>
            <uri>model://jeep/meshes/wheel.stl</uri>
            <scale>1.003700111 0.886200464 0.886200464</scale>
          </mesh>
        </geometry>
        <material>
          <script>
            <uri>file://media/materials/scripts/gazebo.material</uri>
            <name>Gazebo/DarkGrey</name>
          </script>
        </material>
      </visual>
    </link>
    <link name="front_right_wheel">
      <pose>1.082230 -0.71562 0.416970 1.52 0.0 0.0</pose>
      <inertial>
        <mass>12</mass>
        <!-- estimated from http://www.rzrforums.net/wheels-tires/1729-tire-wheel-weights-most-sizes.html -->
        <inertia>
          <ixx>0.5</ixx>
          <ixy>0.0</ixy>
          <iyy>0.5</iyy>
          <ixz>0.0</ixz>
          <iyz>0.0</iyz>
          <izz>1.0</izz>
        </inertia>
      </inertial>
      <collision name="collision">
        <pose>0 0 0.21 0 0.0 0.0</pose>
        <geometry>
          <cylinder>
            <radius>0.417500</radius>
            <length>0.239400</length>
          </cylinder>
        </geometry>
        <max_contacts>1</max_contacts>
        <surface>
          <friction>
            <ode>
              <mu>1.0</mu>
              <mu2>1.0</mu2>
              <fdir1>0 0 1</fdir1>
              <slip1>0.0</slip1>
              <slip2>0.0</slip2>
            </ode>
          </friction>
          <contact>
            <ode>
              <min_depth>0.005</min_depth>
              <kp>1e8</kp>
            </ode>
          </contact>
        </surface>
      </collision>
      <visual name="visual">
        <pose>-0.306300 1.476200 -0.663800 0 1.570796 0</pose>
        <geometry>
          <mesh>
            <uri>model://jeep/meshes/wheel.stl</uri>
            <scale>1.003700111 0.886200464 0.886200464</scale>
          </mesh>
        </geometry>
        <material>
          <script>
            <uri>file://media/materials/scripts/gazebo.material</uri>
            <name>Gazebo/DarkGrey</name>
          </script>
        </material>
      </visual>
    </link>
    <link name="rear_left_wheel">
      <pose>-1.663770 0.71562 0.416970 -1.52 0.0 0.0</pose>
      <inertial>
        <mass>12</mass>
        <!-- estimated from http://www.rzrforums.net/wheels-tires/1729-tire-wheel-weights-most-sizes.html -->
        <inertia>
          <ixx>0.5</ixx>
          <ixy>0.0</ixy>
          <iyy>0.5</iyy>
          <ixz>0.0</ixz>
          <iyz>0.0</iyz>
          <izz>1.0</izz>
        </inertia>
      </inertial>
      <collision name="collision">
        <pose>0 0 0.21 0 0.0 0.0</pose>
        <geometry>
          <cylinder>
            <radius>0.417500</radius>
            <length>0.239400</length>
          </cylinder>
        </geometry>
        <max_contacts>1</max_contacts>
        <surface>
          <friction>
            <ode>
              <mu>1.0</mu>
              <mu2>1.0</mu2>
              <fdir1>0 0 1</fdir1>
              <slip1>0.0</slip1>
              <slip2>0.0</slip2>
            </ode>
          </friction>
          <contact>
            <ode>
              <min_depth>0.005</min_depth>
              <kp>1e8</kp>
            </ode>
          </contact>
        </surface>
      </collision>
      <visual name="visual">
        <pose>0.320000 1.470000 1.130000 0 -1.570800 0</pose>
        <geometry>
          <mesh>
            <uri>model://jeep/meshes/wheel.stl</uri>
            <scale>1.003700111 0.886200464 0.886200464</scale>
          </mesh>
        </geometry>
        <material>
          <script>
            <uri>file://media/materials/scripts/gazebo.material</uri>
            <name>Gazebo/DarkGrey</name>
          </script>
        </material>
      </visual>
    </link>
    <link name="rear_right_wheel">
      <pose>-1.663770 -0.71562 0.416970 1.52 0.0 0.0</pose>
      <inertial>
        <mass>12</mass>
        <!-- estimated from http://www.rzrforums.net/wheels-tires/1729-tire-wheel-weights-most-sizes.html -->
        <inertia>
          <ixx>0.5</ixx>
          <ixy>0.0</ixy>
          <iyy>0.5</iyy>
          <ixz>0.0</ixz>
          <iyz>0.0</iyz>
          <izz>1.0</izz>
        </inertia>
      </inertial>
      <collision name="collision">
        <pose>0 0 0.21 0 0.0 0.0</pose>
        <geometry>
          <cylinder>
            <radius>0.417500</radius>
            <length>0.239400</length>
          </cylinder>
        </geometry>
        <max_contacts>1</max_contacts>
        <surface>
          <friction>
            <ode>
              <mu>1.0</mu>
              <mu2>1.0</mu2>
              <fdir1>0 0 1</fdir1>
              <slip1>0.0</slip1>
              <slip2>0.0</slip2>
            </ode>
          </friction>
          <contact>
            <ode>
              <min_depth>0.005</min_depth>
              <kp>1e8</kp>
            </ode>
          </contact>
        </surface>
      </collision>
      <visual name="visual">
        <pose>-0.310000 1.480000 -0.640000 0 1.570796 0</pose>
        <geometry>
          <mesh>
            <uri>model://jeep/meshes/wheel.stl</uri>
            <scale>1.003700111 0.886200464 0.886200464</scale>
          </mesh>
        </geometry>
        <material>
          <script>
            <uri>file://media/materials/scripts/gazebo.material</uri>
            <name>Gazebo/DarkGrey</name>
          </script>
        </material>
      </visual>
    </link>
    <link name="front_right_wheel_steering_block">
      <pose>1.082230 -0.5 0.416970 1.570796 0.0 0.0</pose>
      <inertial>
        <mass>1</mass>
        <inertia>
          <ixx>0.01</ixx>
          <ixy>0.0</ixy>
          <iyy>0.01</iyy>
          <ixz>0.0</ixz>
          <iyz>0.0</iyz>
          <izz>0.01</izz>
        </inertia>
      </inertial>
      <collision name="collision">
        <geometry>
          <cylinder>
            <radius>0.05</radius>
            <length>0.01</length>
          </cylinder>
        </geometry>
      </collision>
    </link>
    <link name="front_left_wheel_steering_block">
      <pose>1.082230 0.5 0.416970 1.570796 0.0 0.0</pose>
      <inertial>
        <mass>1</mass>
        <inertia>
          <ixx>0.01</ixx>
          <ixy>0.0</ixy>
          <iyy>0.01</iyy>
          <ixz>0.0</ixz>
          <iyz>0.0</iyz>
          <izz>0.01</izz>
        </inertia>
      </inertial>
      <collision name="collision">
        <geometry>
          <cylinder>
            <radius>0.05</radius>
            <length>0.01</length>
          </cylinder>
        </geometry>
      </collision>
    </link>

    <joint type="revolute" name="front_left_steering_joint">
      <child>front_left_wheel_steering_block</child>
      <parent>base_link</parent>
      <axis>
        <xyz>0 0 1</xyz>
        <limit>
          <lower>-0.7727</lower>
          <upper>0.7727</upper>
        </limit>
        <dynamics>
          <damping>50.0</damping>
        </dynamics>
        <use_parent_model_frame>true</use_parent_model_frame>
      </axis>
      <physics>
        <ode>
          <cfm_damping>1</cfm_damping>
          <limit>
            <cfm>0.000000</cfm>
            <erp>0.900000</erp>
          </limit>
        </ode>
      </physics>
    </joint>
    <joint type="revolute" name="front_left_wheel_joint">
      <child>front_left_wheel</child>
      <parent>front_left_wheel_steering_block</parent>
      <axis>
        <xyz>0 1 0.05</xyz>
        <use_parent_model_frame>true</use_parent_model_frame>
      </axis>
    </joint>
    <joint type="revolute" name="front_right_steering_joint">
      <child>front_right_wheel_steering_block</child>
      <parent>base_link</parent>
      <axis>
        <xyz>0 0 1</xyz>
        <limit>
          <lower>-0.7727</lower>
          <upper>0.7727</upper>
        </limit>
        <dynamics>
          <damping>50.0</damping>
        </dynamics>
        <use_parent_model_frame>true</use_parent_model_frame>
      </axis>
      <physics>
        <ode>
          <cfm_damping>1</cfm_damping>
          <limit>
            <cfm>0.000000</cfm>
            <erp>0.900000</erp>
          </limit>
        </ode>
      </physics>
    </joint>
    <joint type="revolute" name="front_right_wheel_joint">
      <child>front_right_wheel</child>
      <parent>front_right_wheel_steering_block</parent>
      <axis>
        <xyz>0 1 -0.05</xyz>
        <use_parent_model_frame>true</use_parent_model_frame>
      </axis>
    </joint>
    <joint type="revolute" name="rear_left_wheel_joint">
      <child>rear_left_wheel</child>
      <parent>base_link</parent>
      <axis>
        <xyz>0 1 0.05</xyz>
        <use_parent_model_frame>true</use_parent_model_frame>
      </axis>
    </joint>
    <joint type="revolute" name="rear_right_wheel_joint">
      <pose>0.0 0.0 -0.1 0 0 0</pose>
      <child>rear_right_wheel</child>
      <parent>base_link</parent>
      <axis>
        <xyz>0 1 -0.05</xyz>
        <use_parent_model_frame>true</use_parent_model_frame>
      </axis>
    </joint>

<!--
    <include>
      <uri>model://gps</uri>
      <pose>0 0 0 0 0 0</pose>
      <name>gps</name>
    </include>
    <joint name='gps_joint' type='fixed'>
      <child>gps::link</child>
      <parent>base_link</parent>
    </joint>
-->


    <plugin name='barometer_plugin' filename='libgazebo_barometer_plugin.so'>
      <robotNamespace/>
      <pubRate>50</pubRate>
      <baroTopic>/baro</baroTopic>
    </plugin>
    <plugin name='gazebo_imu_plugin' filename='libgazebo_imu_plugin.so'>
      <robotNamespace></robotNamespace>
      <linkName>jeep/imu_link</linkName>
      <imuTopic>/imu</imuTopic>
      <gyroscopeNoiseDensity>0.0003394</gyroscopeNoiseDensity>
      <gyroscopeRandomWalk>3.8785e-05</gyroscopeRandomWalk>
      <gyroscopeBiasCorrelationTime>1000.0</gyroscopeBiasCorrelationTime>
      <gyroscopeTurnOnBiasSigma>0.0087</gyroscopeTurnOnBiasSigma>
      <accelerometerNoiseDensity>0.004</accelerometerNoiseDensity>
      <accelerometerRandomWalk>0.006</accelerometerRandomWalk>
      <accelerometerBiasCorrelationTime>300.0</accelerometerBiasCorrelationTime>
      <accelerometerTurnOnBiasSigma>0.196</accelerometerTurnOnBiasSigma>
    </plugin>
    <plugin name='groundtruth_plugin' filename='libgazebo_groundtruth_plugin.so'>
      <robotNamespace/>
    </plugin>
    <plugin name='magnetometer_plugin' filename='libgazebo_magnetometer_plugin.so'>
      <robotNamespace/>
      <pubRate>100</pubRate>
      <noiseDensity>0.0004</noiseDensity>
      <randomWalk>6.4e-06</randomWalk>
      <biasCorrelationTime>600</biasCorrelationTime>
      <magTopic>/mag</magTopic>
    </plugin>
    <plugin filename="libgazebo_ros_skid_steer_drive.so" name="skid_steer_drive_controller">
      <updateRate>100.0</updateRate>
      <robotNamespace>jeep</robotNamespace>
      <leftFrontJoint>front_left_wheel_joint</leftFrontJoint>
      <rightFrontJoint>front_right_wheel_joint</rightFrontJoint>
      <leftRearJoint>rear_left_wheel_joint</leftRearJoint>
      <rightRearJoint>rear_right_wheel_joint</rightRearJoint>
      <wheelSeparation>1.75</wheelSeparation>
      <wheelDiameter>0.835</wheelDiameter>
      <robotBaseFrame>base_link</robotBaseFrame>
      <MaxForce>5.0</MaxForce>
      <torque>200</torque>
      <commandTopic>cmd_vel</commandTopic>
      <odometryTopic>odom</odometryTopic>
      <odometryFrame>odom</odometryFrame>
      <broadcastTF>1</broadcastTF>
    </plugin>
  </model>
</sdf>
